Workbook

Sheet Orders_raw
A1: order_id | B1: customer_id | C1: Customer_Name | D1: order_date | E1: Month | F1: Product_Name | G1: Category | H1: quantity | I1: unit_price | J1: Total_Price | K1: Order_Type | L1: Payment_Method
A2: 5000 | B2: 53 | C2: =IFERROR(_xlfn.XLOOKUP(B2, Customers_raw!A:A, Customers_raw!B:B), "Unknown Customer") -> John Thomas | D2: 45972 | E2: =TEXT(D:D,"YYYY-MM") -> 2025-11 | F2: Memory Foam Pillow | G2: Bedding | H2: 3 | I2: 32 | J2: =H2*I2 -> 96 | K2: =IF(H2<0,"Return","Sale") -> Sale | L2: Paypal
A3: 5001 | B3: 17 | C3: =IFERROR(_xlfn.XLOOKUP(B3, Customers_raw!A:A, Customers_raw!B:B), "Unknown Customer") -> Mary Thomas | D3: 45899 | E3: =TEXT(D:D,"YYYY-MM") -> 2025-08 | F3: Wall Mirror | G3: Home Decor | H3: 1 | I3: 65 | J3: =H3*I3 -> 65 | K3: =IF(H3<0,"Return","Sale") -> Sale | L3: Debit Card
A4: 5002 | B4: 95 | C4: =IFERROR(_xlfn.XLOOKUP(B4, Customers_raw!A:A, Customers_raw!B:B), "Unknown Customer") -> Michelle Martin | D4: 45791 | E4: =TEXT(D:D,"YYYY-MM") -> 2025-05 | F4: Ceramic Mug Set | G4: Kitchen | H4: 3 | I4: 24 | J4: =H4*I4 -> 72 | K4: =IF(H4<0,"Return","Sale") -> Sale | L4: Paypal
A5: 5003 | B5: 86 | C5: =IFERROR(_xlfn.XLOOKUP(B5, Customers_raw!A:A, Customers_raw!B:B), "Unknown Customer") -> Steven Jones | D5: 45719 | E5: =TEXT(D:D,"YYYY-MM") -> 2025-03 | F5: Cotton Bedsheet Set | G5: Bedding | H5: 3 | I5: 55 | J5: =H5*I5 -> 165 | K5: =IF(H5<0,"Return","Sale") -> Sale | L5: Paypal
A6: 5004 | B6: 104 | C6: =IFERROR(_xlfn.XLOOKUP(B6, Customers_raw!A:A, Customers_raw!B:B), "Unknown Customer") -> Christopher Brown | D6: 45939 | E6: =TEXT(D:D,"YYYY-MM") -> 2025-10 | F6: Memory Foam Pillow | G6: Bedding | H6: 2 | I6: 32 | J6: =H6*I6 -> 64 | K6: =IF(H6<0,"Return","Sale") -> Sale | L6: Paypal
A7: 5005 | B7: 71 | C7: =IFERROR(_xlfn.XLOOKUP(B7, Customers_raw!A:A, Customers_raw!B:B), "Unknown Customer") -> Barbara Rodriguez | D7: 45782 | E7: =TEXT(D:D,"YYYY-MM") -> 2025-05 | F7: Table Lamp | G7: Lighting | H7: 1 | I7: 45 | J7: =H7*I7 -> 45 | K7: =IF(H7<0,"Return","Sale") -> Sale | L7: Debit Card
A8: 5006 | B8: 31 | C8: =IFERROR(_xlfn.XLOOKUP(B8, Customers_raw!A:A, Customers_raw!B:B), "Unknown Customer") -> Nancy Harris | D8: 45790 | E8: =TEXT(D:D,"YYYY-MM") -> 2025-05 | F8: String Lights | G8: Lighting | H8: 1 | I8: 18 | J8: =H8*I8 -> 18 | K8: =IF(H8<0,"Return","Sale") -> Sale | L8: Debit Card
A9: 5007 | B9: 68 | C9: =IFERROR(_xlfn.XLOOKUP(B9, Customers_raw!A:A, Customers_raw!B:B), "Unknown Customer") -> James Hernandez | D9: 45998 | E9: =TEXT(D:D,"YYYY-MM") -> 2025-12 | F9: Table Lamp | G9: Lighting | H9: 1 | I9: 42 | J9: =H9*I9 -> 42 | K9: =IF(H9<0,"Return","Sale") -> Sale | L9: Paypal
A10: 5008 | B10: 47 | C10: =IFERROR(_xlfn.XLOOKUP(B10, Customers_raw!A:A, Customers_raw!B:B), "Unknown Customer") -> Christopher Rodriguez | D10: 46009 | E10: =TEXT(D:D,"YYYY-MM") -> 2025-12 | F10: Wall Mirror | G10: Home Decor | H10: 1 | I10: 65 | J10: =H10*I10 -> 65 | K10: =IF(H10<0,"Return","Sale") -> Sale | L10: Credit Card
A11: 5009 | B11: 83 | C11: =IFERROR(_xlfn.XLOOKUP(B11, Customers_raw!A:A, Customers_raw!B:B), "Unknown Customer") -> Mary Martinez | D11: 45938 | E11: =TEXT(D:D,"YYYY-MM") -> 2025-10 | F11: Memory Foam Pillow | G11: Bedding | H11: 1 | I11: 32 | J11: =H11*I11 -> 32 | K11: =IF(H11<0,"Return","Sale") -> Sale | L11: Debit Card
A12: 5010 | B12: 98 | C12: =IFERROR(_xlfn.XLOOKUP(B12, Customers_raw!A:A, Customers_raw!B:B), "Unknown Customer") -> Karen Williams | D12: 45958 | E12: =TEXT(D:D,"YYYY-MM") -> 2025-10 | F12: Memory Foam Pillow | G12: Bedding | H12: 1 | I12: 29 | J12: =H12*I12 -> 29 | K12: =IF(H12<0,"Return","Sale") -> Sale | L12: Credit Card
A13: 5011 | B13: 32 | C13: =IFERROR(_xlfn.XLOOKUP(B13, Customers_raw!A:A, Customers_raw!B:B), "Unknown Customer") -> Kimberly Lopez | D13: 45772 | E13: =TEXT(D:D,"YYYY-MM") -> 2025-04 | F13: Throw Pillow | G13: Home Decor | H13: 1 | I13: 25 | J13: =H13*I13 -> 25 | K13: =IF(H13<0,"Return","Sale") -> Sale | L13: Debit Card
... A429: 5427 | B429: 84 | C429: =IFERROR(_xlfn.XLOOKUP(B429, Customers_raw!A:A, Customers_raw!B:B), "Unknown Customer") -> Kimberly Lewis | D429: 45836 | E429: =TEXT(D:D,"YYYY-MM") -> 2025-06 | F429: Cutting Board | G429: Kitchen | H429: 2 | I429: 19 | J429: =H429*I429 -> 38 | K429: =IF(H429<0,"Return","Sale") -> Sale | L429: Debit Card
A430: 5428 | B430: Unknown | C430: =IFERROR(_xlfn.XLOOKUP(B430, Customers_raw!A:A, Customers_raw!B:B), "Unknown Customer") -> Unknown Customer | D430: 45896 | E430: =TEXT(D:D,"YYYY-MM") -> 2025-08 | F430: Ceramic Vase | G430: Home Decor | H430: 2 | I430: 28 | J430: =H430*I430 -> 56 | K430: =IF(H430<0,"Return","Sale") -> Sale | L430: Debit Card
A431: 5429 | B431: 76 | C431: =IFERROR(_xlfn.XLOOKUP(B431, Customers_raw!A:A, Customers_raw!B:B), "Unknown Customer") -> Thomas Anderson | D431: 45993 | E431: =TEXT(D:D,"YYYY-MM") -> 2025-12 | F431: Wool Blanket | G431: Bedding | H431: 1 | I431: 70 | J431: =H431*I431 -> 70 | K431: =IF(H431<0,"Return","Sale") -> Sale | L431: Paypal
A432: 5430 | B432: 76 | C432: =IFERROR(_xlfn.XLOOKUP(B432, Customers_raw!A:A, Customers_raw!B:B), "Unknown Customer") -> Thomas Anderson | D432: 45945 | E432: =TEXT(D:D,"YYYY-MM") -> 2025-10 | F432: Memory Foam Pillow | G432: Bedding | H432: 2 | I432: 35 | J432: =H432*I432 -> 70 | K432: =IF(H432<0,"Return","Sale") -> Sale | L432: Credit Card
A433: 5431 | B433: 85 | C433: =IFERROR(_xlfn.XLOOKUP(B433, Customers_raw!A:A, Customers_raw!B:B), "Unknown Customer") -> Elizabeth Martinez | D433: 45978 | E433: =TEXT(D:D,"YYYY-MM") -> 2025-11 | F433: Cotton Bedsheet Set | G433: Bedding | H433: 2 | I433: 55 | J433: =H433*I433 -> 110 | K433: =IF(H433<0,"Return","Sale") -> Sale | L433: Debit Card
A434: 5432 | B434: 87 | C434: =IFERROR(_xlfn.XLOOKUP(B434, Customers_raw!A:A, Customers_raw!B:B), "Unknown Customer") -> Joseph Williams | D434: 45820 | E434: =TEXT(D:D,"YYYY-MM") -> 2025-06 | F434: String Lights | G434: Lighting | H434: 1 | I434: 15 | J434: =H434*I434 -> 15 | K434: =IF(H434<0,"Return","Sale") -> Sale | L434: Paypal
A435: 5433 | B435: 3 | C435: =IFERROR(_xlfn.XLOOKUP(B435, Customers_raw!A:A, Customers_raw!B:B), "Unknown Customer") -> Anthony Williams | D435: 45666 | E435: =TEXT(D:D,"YYYY-MM") -> 2025-01 | F435: Throw Pillow | G435: Home Decor | H435: 2 | I435: 25 | J435: =H435*I435 -> 50 | K435: =IF(H435<0,"Return","Sale") -> Sale | L435: Paypal
A436: 5434 | B436: 43 | C436: =IFERROR(_xlfn.XLOOKUP(B436, Customers_raw!A:A, Customers_raw!B:B), "Unknown Customer") -> Sandra Clark | D436: 45767 | E436: =TEXT(D:D,"YYYY-MM") -> 2025-04 | F436: Wool Blanket | G436: Bedding | H436: 1 | I436: 70 | J436: =H436*I436 -> 70 | K436: =IF(H436<0,"Return","Sale") -> Sale | L436: Debit Card
A437: 5435 | B437: 43 | C437: =IFERROR(_xlfn.XLOOKUP(B437, Customers_raw!A:A, Customers_raw!B:B), "Unknown Customer") -> Sandra Clark | D437: 45796 | E437: =TEXT(D:D,"YYYY-MM") -> 2025-05 | F437: Throw Pillow | G437: Home Decor | H437: 3 | I437: 22 | J437: =H437*I437 -> 66 | K437: =IF(H437<0,"Return","Sale") -> Sale | L437: Credit Card
A438: 5436 | B438: 28 | C438: =IFERROR(_xlfn.XLOOKUP(B438, Customers_raw!A:A, Customers_raw!B:B), "Unknown Customer") -> Michael Lopez | D438: 45979 | E438: =TEXT(D:D,"YYYY-MM") -> 2025-11 | F438: Ceramic Mug Set | G438: Kitchen | H438: 2 | I438: 24 | J438: =H438*I438 -> 48 | K438: =IF(H438<0,"Return","Sale") -> Sale | L438: Debit Card
A439: 5437 | B439: 20 | C439: =IFERROR(_xlfn.XLOOKUP(B439, Customers_raw!A:A, Customers_raw!B:B), "Unknown Customer") -> David Ramirez | D439: 45743 | E439: =TEXT(D:D,"YYYY-MM") -> 2025-03 | F439: String Lights | G439: Lighting | H439: 1 | I439: 21 | J439: =H439*I439 -> 21 | K439: =IF(H439<0,"Return","Sale") -> Sale | L439: Credit Card
A440: 5438 | B440: 41 | C440: =IFERROR(_xlfn.XLOOKUP(B440, Customers_raw!A:A, Customers_raw!B:B), "Unknown Customer") -> Margaret Clark | D440: 45968 | E440: =TEXT(D:D,"YYYY-MM") -> 2025-11 | F440: Wool Blanket | G440: Bedding | H440: 1 | I440: 70 | J440: =H440*I440 -> 70 | K440: =IF(H440<0,"Return","Sale") -> Sale | L440: Credit Card
A441: 5439 | B441: 110 | C441: =IFERROR(_xlfn.XLOOKUP(B441, Customers_raw!A:A, Customers_raw!B:B), "Unknown Customer") -> Betty Walker | D441: 45711 | E441: =TEXT(D:D,"YYYY-MM") -> 2025-02 | F441: Wall Mirror | G441: Home Decor | H441: 1 | I441: 68 | J441: =H441*I441 -> 68 | K441: =IF(H441<0,"Return","Sale") -> Sale | L441: Debit Card
A442: 5440 | B442: 46 | C442: =IFERROR(_xlfn.XLOOKUP(B442, Customers_raw!A:A, Customers_raw!B:B), "Unknown Customer") -> Mary Rodriguez | D442: 45709 | E442: =TEXT(D:D,"YYYY-MM") -> 2025-02 | F442: Ceramic Mug Set | G442: Kitchen | H442: 1 | I442: 24 | J442: =H442*I442 -> 24 | K442: =IF(H442<0,"Return","Sale") -> Sale | L442: Credit Card
... A724: 5722 | B724: 52 | C724: =IFERROR(_xlfn.XLOOKUP(B724, Customers_raw!A:A, Customers_raw!B:B), "Unknown Customer") -> Sarah Johnson | D724: 45740 | E724: =TEXT(D:D,"YYYY-MM") -> 2025-03 | F724: Ceramic Vase | G724: Home Decor | H724: 3 | I724: 31 | J724: =H724*I724 -> 93 | K724: =IF(H724<0,"Return","Sale") -> Sale | L724: Credit Card
A725: 5723 | B725: Unknown | C725: =IFERROR(_xlfn.XLOOKUP(B725, Customers_raw!A:A, Customers_raw!B:B), "Unknown Customer") -> Unknown Customer | D725: 45746 | E725: =TEXT(D:D,"YYYY-MM") -> 2025-03 | F725: Table Lamp | G725: Lighting | H725: 1 | I725: 45 | J725: =H725*I725 -> 45 | K725: =IF(H725<0,"Return","Sale") -> Sale | L725: Credit Card
A726: 5724 | B726: 49 | C726: =IFERROR(_xlfn.XLOOKUP(B726, Customers_raw!A:A, Customers_raw!B:B), "Unknown Customer") -> Steven Smith | D726: 45822 | E726: =TEXT(D:D,"YYYY-MM") -> 2025-06 | F726: Table Lamp | G726: Lighting | H726: 3 | I726: 42 | J726: =H726*I726 -> 126 | K726: =IF(H726<0,"Return","Sale") -> Sale | L726: Paypal
A727: 5725 | B727: 70 | C727: =IFERROR(_xlfn.XLOOKUP(B727, Customers_raw!A:A, Customers_raw!B:B), "Unknown Customer") -> Karen Perez | D727: 45692 | E727: =TEXT(D:D,"YYYY-MM") -> 2025-02 | F727: Wall Mirror | G727: Home Decor | H727: 3 | I727: 65 | J727: =H727*I727 -> 195 | K727: =IF(H727<0,"Return","Sale") -> Sale | L727: Debit Card
A728: 5726 | B728: 79 | C728: =IFERROR(_xlfn.XLOOKUP(B728, Customers_raw!A:A, Customers_raw!B:B), "Unknown Customer") -> Nancy Jackson | D728: 45759 | E728: =TEXT(D:D,"YYYY-MM") -> 2025-04 | F728: Wall Mirror | G728: Home Decor | H728: 1 | I728: 68 | J728: =H728*I728 -> 68 | K728: =IF(H728<0,"Return","Sale") -> Sale | L728: Debit Card
A729: 5727 | B729: 62 | C729: =IFERROR(_xlfn.XLOOKUP(B729, Customers_raw!A:A, Customers_raw!B:B), "Unknown Customer") -> Mary Wilson | D729: 45973 | E729: =TEXT(D:D,"YYYY-MM") -> 2025-11 | F729: Cutting Board | G729: Kitchen | H729: 1 | I729: 19 | J729: =H729*I729 -> 19 | K729: =IF(H729<0,"Return","Sale") -> Sale | L729: Debit Card
A730: 5728 | B730: 26 | C730: =IFERROR(_xlfn.XLOOKUP(B730, Customers_raw!A:A, Customers_raw!B:B), "Unknown Customer") -> Betty Johnson | D730: 45973 | E730: =TEXT(D:D,"YYYY-MM") -> 2025-11 | F730: Wool Blanket | G730: Bedding | H730: 3 | I730: 70 | J730: =H730*I730 -> 210 | K730: =IF(H730<0,"Return","Sale") -> Sale | L730: Paypal
A731: 5729 | B731: 17 | C731: =IFERROR(_xlfn.XLOOKUP(B731, Customers_raw!A:A, Customers_raw!B:B), "Unknown Customer") -> Mary Thomas | D731: 45939 | E731: =TEXT(D:D,"YYYY-MM") -> 2025-10 | F731: String Lights | G731: Lighting | H731: 2 | I731: 18 | J731: =H731*I731 -> 36 | K731: =IF(H731<0,"Return","Sale") -> Sale | L731: Credit Card
A732: 5730 | B732: 79 | C732: =IFERROR(_xlfn.XLOOKUP(B732, Customers_raw!A:A, Customers_raw!B:B), "Unknown Customer") -> Nancy Jackson | D732: 45674 | E732: =TEXT(D:D,"YYYY-MM") -> 2025-01 | F732: Non-Stick Pan Set | G732: Kitchen | H732: -1 | I732: 57 | J732: =H732*I732 -> -57 | K732: =IF(H732<0,"Return","Sale") -> Return | L732: Credit Card
A733: 5731 | B733: 80 | C733: =IFERROR(_xlfn.XLOOKUP(B733, Customers_raw!A:A, Customers_raw!B:B), "Unknown Customer") -> Susan Lopez | D733: 45883 | E733: =TEXT(D:D,"YYYY-MM") -> 2025-08 | F733: Table Lamp | G733: Lighting | H733: 3 | I733: 45 | J733: =H733*I733 -> 135 | K733: =IF(H733<0,"Return","Sale") -> Sale | L733: Paypal
A734: 5732 | B734: 26 | C734: =IFERROR(_xlfn.XLOOKUP(B734, Customers_raw!A:A, Customers_raw!B:B), "Unknown Customer") -> Betty Johnson | D734: 45982 | E734: =TEXT(D:D,"YYYY-MM") -> 2025-11 | F734: String Lights | G734: Lighting | H734: 2 | I734: 15 | J734: =H734*I734 -> 30 | K734: =IF(H734<0,"Return","Sale") -> Sale | L734: Debit Card
A735: 5733 | B735: 9 | C735: =IFERROR(_xlfn.XLOOKUP(B735, Customers_raw!A:A, Customers_raw!B:B), "Unknown Customer") -> Andrew Anderson | D735: 45669 | E735: =TEXT(D:D,"YYYY-MM") -> 2025-01 | F735: Throw Pillow | G735: Home Decor | H735: 1 | I735: 22 | J735: =H735*I735 -> 22 | K735: =IF(H735<0,"Return","Sale") -> Sale | L735: Debit Card
A736: 5734 | B736: 36 | C736: =IFERROR(_xlfn.XLOOKUP(B736, Customers_raw!A:A, Customers_raw!B:B), "Unknown Customer") -> Daniel Harris | D736: 45702 | E736: =TEXT(D:D,"YYYY-MM") -> 2025-02 | F736: Floor Lamp | G736: Lighting | H736: 2 | I736: 92 | J736: =H736*I736 -> 184 | K736: =IF(H736<0,"Return","Sale") -> Sale | L736: Credit Card
...

Sheet Customers_raw
A1: Customer_id | B1: Customer_Name | C1: Email | D1: City | E1: Signup_Date
A2: 1 | B2: Christopher Jones | C2: Christopher.Jones75@Gmail.Com | D2: Seattle | E2: 45341
A3: 2 | B3: Michael Lopez | C3: Michael.Lopez39@Gmail.Com | D3: Austin | E3: 45511
A4: 3 | B4: Anthony Williams | C4: Unknown | D4: Chicago | E4: 45856
A5: 4 | B5: Joshua Brown | C5: Joshua.Brown597@Gmail.Com | D5: Chicago | E5: 45934
A6: 5 | B6: Joshua Martin | C6: Joshua.Martin48@Gmail.Com | D6: Seattle | E6: 45518
A7: 6 | B7: David Martinez | C7: David.Martinez121@Gmail.Com | D7: Seattle | E7: 45845
A8: 7 | B8: Emily Ramirez | C8: Emily.Ramirez585@Gmail.Com | D8: Portland | E8: 45887
A9: 8 | B9: Lisa Brown | C9: Lisa.Brown634@Gmail.Com | D9: Denver | E9: 45353
A10: 9 | B10: Andrew Anderson | C10: Andrew.Anderson946@Gmail.Com | D10: Atlanta | E10: 45891
A11: 10 | B11: Karen Davis | C11: Karen.Davis589@Gmail.Com | D11: Portland | E11: 45375
A12: 11 | B12: Ashley Robinson | C12: Ashley.Robinson624@Gmail.Com | D12: Atlanta | E12: 45586
A13: 12 | B13: Linda Moore | C13: Linda.Moore156@Gmail.Com | D13: Seattle | E13: 45642
... A111: 110 | B111: Betty Walker | C111: Betty.Walker51@Gmail.Com | D111: Chicago | E111: 45374

Sheet Pivot_Table
A1: Monthly Revenue by Category
I2: Monthly Sales – 2025
A3: Sum of Total_Price | B3: Column Labels
A4: Row Labels | B4: Bedding | C4: Home Decor | D4: Kitchen | E4: Lighting | F4: Grand Total | I4: Row Labels | J4: Sum of Total_Price
A5: 2025-01 | B5: 2575 | C5: 1336.1417 | D5: 1223.1905 | E5: 1539.6429 | F5: 6673.9751 | I5: 2025-01 | J5: 6673.9751
A6: 2025-02 | B6: 2271.7941 | C6: 2149.1472 | D6: 1311.7143 | E6: 2093 | F6: 7825.6556 | I6: 2025-02 | J6: 7825.6556
A7: 2025-03 | B7: 2264.8788 | C7: 1949 | D7: 1263.419 | E7: 2679.4327 | F7: 8156.7305 | I7: 2025-03 | J7: 8156.7305
A8: 2025-04 | B8: 1460.7941 | C8: 1740.3 | D8: 832.44762 | E8: 1723.2885 | F8: 5756.8302 | I8: 2025-04 | J8: 5756.8302
A9: 2025-05 | B9: 2065.0669 | C9: 1495.1 | D9: 876.13187 | E9: 2480.4327 | F9: 6916.7314 | I9: 2025-05 | J9: 6916.7314
A10: 2025-06 | B10: 1866 | C10: 1828 | D10: 1591.7143 | E10: 1934.7015 | F10: 7220.4158 | I10: 2025-06 | J10: 7220.4158
A11: 2025-07 | B11: 3014 | C11: 2042.2362 | D11: 1536.6762 | E11: 1936.988 | F11: 8529.9004 | I11: 2025-07 | J11: 8529.9004
A12: 2025-08 | B12: 1919 | C12: 1980.389 | D12: 1397 | E12: 2343.4544 | F12: 7639.8434 | I12: 2025-08 | J12: 7639.8434
A13: 2025-09 | B13: 2247.1546 | C13: 1234.1 | D13: 1015.1319 | E13: 1383 | F13: 5879.3865 | I13: 2025-09 | J13: 5879.3865
A14: 2025-10 | B14: 2378.4639 | C14: 1328.6545 | D14: 1660 | E14: 1947.5957 | F14: 7314.7142 | I14: 2025-10 | J14: 7314.7142
A15: 2025-11 | B15: 2529.7398 | C15: 1406 | D15: 1266 | E15: 3049 | F15: 8250.7398 | I15: 2025-11 | J15: 8250.7398
A16: 2025-12 | B16: 2368.5704 | C16: 1172.6727 | D16: 1557.1905 | E16: 1593.0217 | F16: 6691.4554 | I16: 2025-12 | J16: 6691.4554
A17: Grand Total | B17: 26960.463 | C17: 19661.741 | D17: 15530.616 | E17: 24703.558 | F17: 86856.378 | I17: Grand Total | J17: 86856.378
A37: Top 10 Customers by Total Spend
A39: Row Labels | B39: Sum of Total_Price
A40: Betty Johnson | B40: 1694.4173
A41: Betty Moore | B41: 1479
A42: Jennifer White | B42: 1649
A43: Joshua Martin | B43: 1686
A44: Karen Clark | B44: 1908.0945
A45: Karen Perez | B45: 2000
A46: Michael Lopez | B46: 1859.1417
A47: Michael Moore | B47: 1588
A48: Thomas Lopez | B48: 1559.4592
A49: Thomas Ramirez | B49: 1874.7309
A52: Return Rate (%)
A54: =COUNTIF(Orders_raw!K:K,"Return") / COUNTA(Orders_raw!K:K) -> 0.035357417
