Workbook

Sheet orders_raw
A1: order_id | B1: customer_id | C1: Customer_Name | D1: Order_Date | E1: Product_Name | F1: Category | G1: quantity | H1: Order_Type | I1: unit_price | J1: payment_method | K1: Total_Price | L1: Month
A2: 1000 | B2: 23 | C2: =IFERROR(_xlfn.XLOOKUP(B2, Customer!A:A, Customer!B:B), "Unknown Customer") -> Milad Rezaei | D2: 45665 | E2: Iced Latte | F2: Cold Drinks | G2: 1 | H2: Bought | I2: 57000 | J2: Online | K2: =G2*I2 -> 57000 | L2: =TEXT(D2,"YYYY-MM") -> 2025-01
A3: 1001 | B3: 96 | C3: =IFERROR(_xlfn.XLOOKUP(B3, Customer!A:A, Customer!B:B), "Unknown Customer") -> Milad Norouzi | D3: 45984 | E3: Latte | F3: Hot Drinks | G3: 4 | H3: Bought | I3: 53000 | J3: card | K3: =G3*I3 -> 212000 | L3: =TEXT(D3,"YYYY-MM") -> 2025-11
A4: 1002 | B4: 62 | C4: =IFERROR(_xlfn.XLOOKUP(B4, Customer!A:A, Customer!B:B), "Unknown Customer") -> Amir Mousavi | D4: 45832 | E4: Chocolate Cake | F4: Bakery | G4: 1 | H4: Bought | I4: 75000 | J4: card | K4: =G4*I4 -> 75000 | L4: =TEXT(D4,"YYYY-MM") -> 2025-06
A5: 1003 | B5: 63 | C5: =IFERROR(_xlfn.XLOOKUP(B5, Customer!A:A, Customer!B:B), "Unknown Customer") -> Golnaz Rezaei | D5: 45953 | E5: Cappuccino | F5: Hot Drinks | G5: 1 | H5: Bought | I5: 55000 | J5: Card | K5: =G5*I5 -> 55000 | L5: =TEXT(D5,"YYYY-MM") -> 2025-10
A6: 1004 | B6: 32 | C6: =IFERROR(_xlfn.XLOOKUP(B6, Customer!A:A, Customer!B:B), "Unknown Customer") -> Elham Karimi | D6: 45943 | E6: Cappuccino | F6: Hot Drinks | G6: 4 | H6: Bought | I6: 60000 | J6: card | K6: =G6*I6 -> 240000 | L6: =TEXT(D6,"YYYY-MM") -> 2025-10
A7: 1005 | B7: 39 | C7: =IFERROR(_xlfn.XLOOKUP(B7, Customer!A:A, Customer!B:B), "Unknown Customer") -> Mona Ghasemi | D7: 45877 | E7: Blueberry Muffin | F7: Bakery | G7: 2 | H7: Bought | I7: 45000 | J7: Online | K7: =G7*I7 -> 90000 | L7: =TEXT(D7,"YYYY-MM") -> 2025-08
A8: 1006 | B8: 85 | C8: =IFERROR(_xlfn.XLOOKUP(B8, Customer!A:A, Customer!B:B), "Unknown Customer") -> Sepideh Yousefi | D8: 45738 | E8: Cappuccino | F8: Hot Drinks | G8: 2 | H8: Bought | I8: 50000 | J8: card | K8: =G8*I8 -> 100000 | L8: =TEXT(D8,"YYYY-MM") -> 2025-03
A9: 1007 | B9: 58 | C9: =IFERROR(_xlfn.XLOOKUP(B9, Customer!A:A, Customer!B:B), "Unknown Customer") -> Mona Moradi | D9: 45668 | E9: Hot Chocolate | F9: Hot Drinks | G9: 1 | H9: Bought | I9: 60000 | J9: Online | K9: =G9*I9 -> 60000 | L9: =TEXT(D9,"YYYY-MM") -> 2025-01
A10: 1008 | B10: 111 | C10: =IFERROR(_xlfn.XLOOKUP(B10, Customer!A:A, Customer!B:B), "Unknown Customer") -> Sepideh Yousefi | D10: 45694 | E10: Chocolate Cake | F10: Bakery | G10: 1 | H10: Bought | I10: 80000 | J10: card | K10: =G10*I10 -> 80000 | L10: =TEXT(D10,"YYYY-MM") -> 2025-02
A11: 1009 | B11: 15 | C11: =IFERROR(_xlfn.XLOOKUP(B11, Customer!A:A, Customer!B:B), "Unknown Customer") -> Milad Zare | D11: 45773 | E11: Cheesecake | F11: Bakery | G11: 1 | H11: Bought | I11: 85000 | J11: Cash | K11: =G11*I11 -> 85000 | L11: =TEXT(D11,"YYYY-MM") -> 2025-04
A12: 1010 | B12: 102 | C12: =IFERROR(_xlfn.XLOOKUP(B12, Customer!A:A, Customer!B:B), "Unknown Customer") -> Yasaman Yousefi | D12: 45668 | E12: Iced Latte | F12: Cold Drinks | G12: 2 | H12: Bought | I12: 57000 | J12: Online | K12: =G12*I12 -> 114000 | L12: =TEXT(D12,"YYYY-MM") -> 2025-01
A13: 1011 | B13: 52 | C13: =IFERROR(_xlfn.XLOOKUP(B13, Customer!A:A, Customer!B:B), "Unknown Customer") -> Kaveh Rostami | D13: 45914 | E13: Iced Latte | F13: Cold Drinks | G13: 2 | H13: Bought | I13: 57000 | J13: card | K13: =G13*I13 -> 114000 | L13: =TEXT(D13,"YYYY-MM") -> 2025-09
... A1395: 2399 | B1395: 48 | C1395: =IFERROR(_xlfn.XLOOKUP(B1395, Customer!A:A, Customer!B:B), "Unknown Customer") -> Hamed Jafari | D1395: 45971 | E1395: Espresso | F1395: Hot Drinks | G1395: 3 | H1395: Bought | I1395: 45000 | J1395: card | K1395: =G1395*I1395 -> 135000 | L1395: =TEXT(D1395,"YYYY-MM") -> 2025-11

Sheet Customer
A1: customer_id | B1: Customer_Name | C1: email | D1: City | E1: signup_date
A2: 1 | B2: Leila Rezaei | C2: leila.rezaei229@gmail.com | D2: Tehran | E2: 45542
A3: 2 | B3: Reza Naderi | C3: reza.naderi31@gmail.com | D3: Esfahan | E3: 45324
A4: 3 | B4: Hamed Abbasi | C4: hamed.abbasi734@gmail.com | D4: Tehran | E4: 45495
A5: 4 | B5: Kaveh Salehi | C5: kaveh.salehi285@gmail.com | D5: Mashhad | E5: 45895
A6: 5 | B6: Sara Sadeghi | C6: sara.sadeghi160@gmail.com | D6: Qom | E6: 45576
A7: 6 | B7: Sepideh Mousavi | C7: sepideh.mousavi100@gmail.com | D7: Esfahan | E7: 45681
A8: 7 | B8: Farhad Vakili | C8: farhad.vakili550@gmail.com | D8: Tabriz | E8: 45762
A9: 8 | B9: Milad Norouzi | C9: milad.norouzi634@gmail.com | D9: Esfahan | E9: 45935
A10: 9 | B10: Farhad Zare | C10: farhad.zare47@gmail.com | D10: Mashhad | E10: 45363
A11: 10 | B11: Sepideh Rostami | C11: sepideh.rostami390@gmail.com | D11: Esfahan | E11: 45395
A12: 11 | B12: Leila Kazemi | C12: leila.kazemi215@gmail.com | D12: Shiraz | E12: 45655
A13: 12 | B13: Golnaz Karimi | C13: golnaz.karimi474@gmail.com | D13: Shiraz | E13: 45459
... A121: 120 | B121: Sepideh Abbasi | C121: sepideh.abbasi304@gmail.com | D121: Tabriz | E121: 45490

Sheet Pivot Table
A1: Sum of Total_Price | B1: Column Labels
A2: Row Labels | B2: Bakery | C2: Cold Drinks | D2: Hot Drinks | E2: Grand Total
A3: 2025-01 | B3: 5127142.9 | C3: 2361265.5 | D3: 6133320 | E3: 13621728
A4: 2025-02 | B4: 5366370 | C4: 2206000 | D4: 7018935.3 | E4: 14591305
A5: 2025-03 | B5: 4025000 | C5: 2354376.1 | D5: 5330960 | E5: 11710336
A6: 2025-04 | B6: 4376714.3 | C6: 2486182.9 | D6: 3651782.9 | E6: 10514680
A7: 2025-05 | B7: 2796399.3 | C7: 1882458.7 | D7: 5413936.2 | E7: 10092794
A8: 2025-06 | B8: 4500000 | C8: 2169000 | D8: 4883707.5 | E8: 11552708
A9: 2025-07 | B9: 5521428.6 | C9: 1924917.4 | D9: 5393000 | E9: 12839346
A10: 2025-08 | B10: 4959841.1 | C10: 1750531 | D10: 4410032.4 | E10: 11120405
A11: 2025-09 | B11: 3804739.6 | C11: 2141000 | D11: 5328992.4 | E11: 11274732
A12: 2025-10 | B12: 3195256.4 | C12: 2680531 | D12: 5969482.3 | E12: 11845270
A13: 2025-11 | B13: 3804958.3 | C13: 3746000 | D13: 5580918.7 | E13: 13131877
A14: 2025-12 | B14: 4180000 | C14: 2206000 | D14: 6513419.4 | E14: 12899419
A15: Grand Total | B15: 51657850 | C15: 27908263 | D15: 65628487 | E15: 1.451946e+08
A22: Row Labels | B22: Sum of Total_Price
A23: Elham Karimi | B23: 6385285.7
A24: Milad Norouzi | B24: 4142000
A25: Payam Jafari | B25: 3382098.7
A26: Sepideh Yousefi | B26: 3239000
A27: Leila Kazemi | B27: 3115000
A28: Sina Ghasemi | B28: 3017113.6
A29: Mona Moradi | B29: 2745173.7
A30: Niloofar Ebrahimi | B30: 2661000
A31: Milad Yousefi | B31: 2036857.1
A32: Elham Norouzi | B32: 1993000
A33: Grand Total | B33: 32716529
A42: Row Labels | B42: Sum of Total_Price
A43: 2025-01 | B43: 13621728
A44: 2025-02 | B44: 14591305
A45: 2025-03 | B45: 11710336
A46: 2025-04 | B46: 10514680
A47: 2025-05 | B47: 10092794
A48: 2025-06 | B48: 11552708
A49: 2025-07 | B49: 12839346
A50: 2025-08 | B50: 11120405
A51: 2025-09 | B51: 11274732
A52: 2025-10 | B52: 11845270
A53: 2025-11 | B53: 13131877
A54: 2025-12 | B54: 12899419
...

Sheet Dashboard
A1: Sum count of orders | B1: sum count of returned orders | C1: Percent of returns
A2: =COUNTA(orders_raw!G:G) -> 1395 | B2: =COUNTIF(orders_raw!H:H,"Return") -> 41 | C2: =COUNTIF(orders_raw!H:H,"Return") / COUNTA(orders_raw!G:G) -> 0.029390681
